<?xml version="1.0" encoding="utf-8"?>
<!-- This URDF was automatically created by SolidWorks to URDF Exporter! Originally created by Stephen Brawner (brawner@gmail.com) 
     Commit Version: 1.5.1-0-g916b5db  Build Version: 1.5.7152.31018
     For more information, please see http://wiki.ros.org/sw_urdf_exporter -->
<robot
  name="mat150621">

<link name="world"/>

  <joint
    name="dummy"
    type="fixed">
    <parent
      link="world" />
    <child
      link="base_link" />
  </joint>

  <link
    name="base_link">
    <inertial>
      <origin
        xyz="-0.041968 -0.042973 0.059275"
        rpy="0 0 0" />
      <mass
        value="658.29" />
      <inertia
        ixx="38.105"
        ixy="0.0004935"
        ixz="-4.8562E-06"
        iyy="38.103"
        iyz="2.3872E-05"
        izz="74.68" />
    </inertial>
    <visual>
      <origin
        xyz="0 0 0"
        rpy="0 0 0" />
      <geometry>
        <mesh
          filename="package://mat150621/meshes/base_link.STL" />
      </geometry>
      <material
        name="">
        <color
          rgba="0.83922 0.46667 0.36863 1" />
      </material>
    </visual>
    <collision>
      <origin
        xyz="0 0 0"
        rpy="0 0 0" />
      <geometry>
        <mesh
          filename="package://mat150621/meshes/base_link.STL" />
      </geometry>
    </collision>
  </link>
  <link
    name="link_1">
    <inertial>
      <origin
        xyz="-0.033996 0.093779 0.0012329"
        rpy="0 0 0" />
      <mass
        value="0.66771" />
      <inertia
        ixx="0.00059176"
        ixy="4.1059E-06"
        ixz="1.5829E-07"
        iyy="0.00079133"
        iyz="-2.7619E-09"
        izz="0.00082307" />
    </inertial>
    <visual>
      <origin
        xyz="0 0 0"
        rpy="0 0 0" />
      <geometry>
        <mesh
          filename="package://mat150621/meshes/link_1.STL" />
      </geometry>
      <material
        name="">
        <color
          rgba="1 1 1 0.32" />
      </material>
    </visual>
    <collision>
      <origin
        xyz="0 0 0"
        rpy="0 0 0" />
      <geometry>
        <mesh
          filename="package://mat150621/meshes/link_1.STL" />
      </geometry>
    </collision>
  </link>
  <joint
    name="joint_1"
    type="continuous">
    <origin
      xyz="-0.041992 -0.042857 0.078"
      rpy="1.5708 0 -1.3701" />
    <parent
      link="base_link" />
    <child
      link="link_1" />
    <axis
      xyz="0 1 0" />
    <limit
      lower="0"
      upper="0"
      effort="10000"
      velocity="0.01" />
  </joint>
  <link
    name="link_2">
    <inertial>
      <origin
        xyz="-0.090237 -0.041077 0.0071264"
        rpy="0 0 0" />
      <mass
        value="0.71052" />
      <inertia
        ixx="0.0014201"
        ixy="-0.0013787"
        ixz="-6.3697E-18"
        iyy="0.0030114"
        iyz="-3.9031E-18"
        izz="0.0035692" />
    </inertial>
    <visual>
      <origin
        xyz="0 0 0"
        rpy="0 0 0" />
      <geometry>
        <mesh
          filename="package://mat150621/meshes/link_2.STL" />
      </geometry>
      <material
        name="">
        <color
          rgba="1 1 1 0.32" />
      </material>
    </visual>
    <collision>
      <origin
        xyz="0 0 0"
        rpy="0 0 0" />
      <geometry>
        <mesh
          filename="package://mat150621/meshes/link_2.STL" />
      </geometry>
    </collision>
  </link>
  <joint
    name="joint_2"
    type="continuous">
    <origin
      xyz="-0.094526 0.1845 0"
      rpy="0 0 -2.0944" />
    <parent
      link="link_1" />
    <child
      link="link_2" />
    <axis
      xyz="0 0 1" />
    <limit
      lower="0"
      upper="0"
      effort="10000"
      velocity="0.01" />
  </joint>
  <link
    name="link_3">
    <inertial>
      <origin
        xyz="0.023622 -0.0034545 -0.077955"
        rpy="0 0 0" />
      <mass
        value="0.20995" />
      <inertia
        ixx="0.0001298"
        ixy="-7.756E-06"
        ixz="6.8402E-08"
        iyy="0.00011907"
        iyz="3.0211E-07"
        izz="9.4044E-05" />
    </inertial>
    <visual>
      <origin
        xyz="0 0 0"
        rpy="0 0 0" />
      <geometry>
        <mesh
          filename="package://mat150621/meshes/link_3.STL" />
      </geometry>
      <material
        name="">
        <color
          rgba="1 1 1 0.32" />
      </material>
    </visual>
    <collision>
      <origin
        xyz="0 0 0"
        rpy="0 0 0" />
      <geometry>
        <mesh
          filename="package://mat150621/meshes/link_3.STL" />
      </geometry>
    </collision>
  </link>
  <joint
    name="joint_3"
    type="continuous">
    <origin
      xyz="-0.31697 -0.172 0.05541"
      rpy="3.1416 0 1.5595" />
    <parent
      link="link_2" />
    <child
      link="link_3" />
    <axis
      xyz="0 0 1" />
    <limit
      lower="0"
      upper="0"
      effort="10000"
      velocity="0.01" />
  </joint>
  <link
    name="link_4">
    <inertial>
      <origin
        xyz="0.012568 -0.0056712 0.12711"
        rpy="0 0 0" />
      <mass
        value="0.46439" />
      <inertia
        ixx="0.0017693"
        ixy="-1.7931E-05"
        ixz="-0.00025886"
        iyy="0.0018075"
        iyz="-0.00012453"
        izz="0.00034226" />
    </inertial>
    <visual>
      <origin
        xyz="0 0 0"
        rpy="0 0 0" />
      <geometry>
        <mesh
          filename="package://mat150621/meshes/link_4.STL" />
      </geometry>
      <material
        name="">
        <color
          rgba="1 1 1 0.32" />
      </material>
    </visual>
    <collision>
      <origin
        xyz="0 0 0"
        rpy="0 0 0" />
      <geometry>
        <mesh
          filename="package://mat150621/meshes/link_4.STL" />
      </geometry>
    </collision>
  </link>
  <joint
    name="joint_4"
    type="continuous">
    <origin
      xyz="0 0 -0.10734"
      rpy="-1.5708 0 2.6067" />
    <parent
      link="link_3" />
    <child
      link="link_4" />
    <axis
      xyz="0 0 1" />
    <limit
      lower="0"
      upper="0"
      effort="10000"
      velocity="0.01" />
  </joint>
  <link
    name="link_5">
    <inertial>
      <origin
        xyz="-0.0183367864154505 -8.13238365537927E-15 -0.000490864933980428"
        rpy="0 0 0" />
      <mass
        value="0.0755005716858459" />
      <inertia
        ixx="1.97589257555594E-05"
        ixy="5.25160427297666E-20"
        ixz="6.05450831115173E-07"
        iyy="4.31691452452356E-05"
        iyz="1.00585162486448E-21"
        izz="4.5866156286482E-05" />
    </inertial>
    <visual>
      <origin
        xyz="0 0 0"
        rpy="0 0 0" />
      <geometry>
        <mesh
          filename="package://mat150621/meshes/link_5.STL" />
      </geometry>
      <material
        name="">
        <color
          rgba="0 0 1 0.32" />
      </material>
    </visual>
    <collision>
      <origin
        xyz="0 0 0"
        rpy="0 0 0" />
      <geometry>
        <mesh
          filename="package://mat150621/meshes/link_5.STL" />
      </geometry>
    </collision>
  </link>
  <joint
    name="joint_5"
    type="continuous">
    <origin
      xyz="0 0.00018906 0.2605"
      rpy="3.1416 0 -3.1416" />
    <parent
      link="link_4" />
    <child
      link="link_5" />
    <axis
      xyz="1 0 0" />
    <limit
      lower="0"
      upper="0"
      effort="10000"
      velocity="0.01" />
  </joint>
  <link
    name="link_6">
    <inertial>
      <origin
        xyz="4.8572E-17 -2.7756E-17 -0.058506"
        rpy="0 0 0" />
      <mass
        value="0.51132" />
      <inertia
        ixx="0.00018374"
        ixy="3.3881E-21"
        ixz="1.2594E-19"
        iyy="0.00018956"
        iyz="-2.0157E-20"
        izz="6.1205E-05" />
    </inertial>
    <visual>
      <origin
        xyz="0 0 0"
        rpy="0 0 0" />
      <geometry>
        <mesh
          filename="package://mat150621/meshes/link_6.STL" />
      </geometry>
      <material
        name="">
        <color
          rgba="0.52941 0.54902 0.54902 1" />
      </material>
    </visual>
    <collision>
      <origin
        xyz="0 0 0"
        rpy="0 0 0" />
      <geometry>
        <mesh
          filename="package://mat150621/meshes/link_6.STL" />
      </geometry>
    </collision>
  </link>
  <joint
    name="joint_6"
    type="fixed">
    <origin
      xyz="-0.002 0 -0.0555"
      rpy="3.1416 0 3.1416" />
    <parent
      link="link_5" />
    <child
      link="link_6" />
    <axis
      xyz="0 0 0" />
  </joint>
  <link
    name="gripper_1">
    <inertial>
      <origin
        xyz="-0.00445345514667091 -1.93456362040934E-14 0.0101363636363627"
        rpy="0 0 0" />
      <mass
        value="0.0078936" />
      <inertia
        ixx="3.37333218181819E-07"
        ixy="1.1090175908621E-19"
        ixz="3.10300116957153E-21"
        iyy="2.88583218181819E-07"
        iyz="2.34395263746486E-21"
        izz="8.13123999999998E-08" />
    </inertial>
    <visual>
      <origin
        xyz="0 0 0"
        rpy="0 0 0" />
      <geometry>
        <mesh
          filename="package://mat150621/meshes/gripper_1.STL" />
      </geometry>
      <material
        name="">
        <color
          rgba="0.529411764705882 0.549019607843137 0.549019607843137 1" />
      </material>
    </visual>
    <collision>
      <origin
        xyz="0 0 0"
        rpy="0 0 0" />
      <geometry>
        <mesh
          filename="package://mat150621/meshes/gripper_1.STL" />
      </geometry>
    </collision>
  </link>
  <joint
    name="grip_1"
    type="prismatic">
    <origin
      xyz="0.0095465 0 0.02"
      rpy="3.1416 0 -3.1416" />
    <parent
      link="link_6" />
    <child
      link="gripper_1" />
    <axis
      xyz="1 0 0" />
    <limit
      lower="0"
      upper="0"
      effort="1000000"
      velocity="0.01" />
  </joint>
  <link
    name="gripper_2">
    <inertial>
      <origin
        xyz="0.0044535 5.4956E-15 0.010136"
        rpy="0 0 0" />
      <mass
        value="0.0078936" />
      <inertia
        ixx="3.3733E-07"
        ixy="1.2035E-19"
        ixz="-9.0704E-20"
        iyy="2.8858E-07"
        iyz="-7.3587E-20"
        izz="8.1312E-08" />
    </inertial>
    <visual>
      <origin
        xyz="0 0 0"
        rpy="0 0 0" />
      <geometry>
        <mesh
          filename="package://mat150621/meshes/gripper_2.STL" />
      </geometry>
      <material
        name="">
        <color
          rgba="0.52941 0.54902 0.54902 1" />
      </material>
    </visual>
    <collision>
      <origin
        xyz="0 0 0"
        rpy="0 0 0" />
      <geometry>
        <mesh
          filename="package://mat150621/meshes/gripper_2.STL" />
      </geometry>
    </collision>
  </link>
  <joint
    name="grip_2"
    type="prismatic">
    <origin
      xyz="-0.0095465 0 0.02"
      rpy="-3.1416 0 -3.1416" />
    <parent
      link="link_6" />
    <child
      link="gripper_2" />
    <axis
      xyz="1 0 0" />
    <limit
      lower="0"
      upper="0"
      effort="10000"
      velocity="0.01" />
  </joint>

  <transmission name="tran1">
    <type>transmission_interface/SimpleTransmission</type>
    <joint name="joint_1">
      <hardwareInterface>hardware_interface/EffortJointInterface</hardwareInterface>
    </joint>
    <actuator name="motor1">
      <hardwareInterface>hardware_interface/EffortJointInterface</hardwareInterface>
      <mechanicalReduction>1</mechanicalReduction>
    </actuator>
  </transmission>

  <transmission name="tran2">
    <type>transmission_interface/SimpleTransmission</type>
    <joint name="joint_2">
      <hardwareInterface>hardware_interface/EffortJointInterface</hardwareInterface>
    </joint>
    <actuator name="motor2">
      <hardwareInterface>hardware_interface/EffortJointInterface</hardwareInterface>
      <mechanicalReduction>1</mechanicalReduction>
    </actuator>
  </transmission>

  <transmission name="tran3">
    <type>transmission_interface/SimpleTransmission</type>
    <joint name="joint_3">
      <hardwareInterface>hardware_interface/EffortJointInterface</hardwareInterface>
    </joint>
    <actuator name="motor3">
      <hardwareInterface>hardware_interface/EffortJointInterface</hardwareInterface>
      <mechanicalReduction>1</mechanicalReduction>
    </actuator>
  </transmission>

  <transmission name="tran4">
    <type>transmission_interface/SimpleTransmission</type>
    <joint name="joint_4">
      <hardwareInterface>hardware_interface/EffortJointInterface</hardwareInterface>
    </joint>
    <actuator name="motor4">
      <hardwareInterface>hardware_interface/EffortJointInterface</hardwareInterface>
      <mechanicalReduction>1</mechanicalReduction>
    </actuator>
  </transmission>

<transmission name="tran5">
    <type>transmission_interface/SimpleTransmission</type>
    <joint name="joint_5">
      <hardwareInterface>hardware_interface/EffortJointInterface</hardwareInterface>
    </joint>
    <actuator name="motor5">
      <hardwareInterface>hardware_interface/EffortJointInterface</hardwareInterface>
      <mechanicalReduction>1</mechanicalReduction>
    </actuator>
  </transmission>

 <transmission name="tran6">
    <type>transmission_interface/SimpleTransmission</type>
    <joint name="grip_1">
      <hardwareInterface>hardware_interface/EffortJointInterface</hardwareInterface>
    </joint>
    <actuator name="motor6">
      <hardwareInterface>hardware_interface/EffortJointInterface</hardwareInterface>
      <mechanicalReduction>1</mechanicalReduction>
    </actuator>
  </transmission>

 <transmission name="tran7">
    <type>transmission_interface/SimpleTransmission</type>
    <joint name="grip_2">
      <hardwareInterface>hardware_interface/EffortJointInterface</hardwareInterface>
    </joint>
    <actuator name="motor7">
      <hardwareInterface>hardware_interface/EffortJointInterface</hardwareInterface>
      <mechanicalReduction>1</mechanicalReduction>
    </actuator>
  </transmission>

<gazebo reference="base_link">
    <material>Gazebo/Yellow</material>
    <turnGravityOff>true</turnGravityOff>
  </gazebo>
  <gazebo reference="link_1">
    <material>Gazebo/Orange</material>
    <turnGravityOff>true</turnGravityOff>
  </gazebo>
  <gazebo reference="link_2">
    <material>Gazebo/Orange</material>
    <turnGravityOff>true</turnGravityOff>
  </gazebo>  
  <gazebo reference="link_3">
    <material>Gazebo/Orange</material>
    <turnGravityOff>true</turnGravityOff>
  </gazebo>
  <gazebo reference="link_4">
    <material>Gazebo/Orange</material>
    <turnGravityOff>true</turnGravityOff>
  </gazebo>
  <gazebo reference="link_5">
    <material>Gazebo/Orange</material>
    <turnGravityOff>true</turnGravityOff>
  </gazebo>
  <gazebo reference="link_6">
    <material>Gazebo/Orange</material>
    <turnGravityOff>true</turnGravityOff>
  </gazebo>
  <gazebo reference="gripper_1">
    <material>Gazebo/Orange</material>
    <turnGravityOff>true</turnGravityOff>
  </gazebo>
  <gazebo reference="gripper_2">
    <material>Gazebo/Orange</material>
    <turnGravityOff>true</turnGravityOff>
  </gazebo>

  <gazebo>
      <plugin name="gazebo_ros_control" filename="libgazebo_ros_control.so">
        <robotNamespace>/mat150621</robotNamespace>
        <robotParam>robot_description</robotParam>
        <controlPeriod>0.001</controlPeriod>
        <robotSimType>gazebo_ros_control/DefaultRobotHWSim</robotSimType>
        <legacyModeNS>true</legacyModeNS>
      </plugin>
  </gazebo>
</robot>